Workbook

Sheet Dashboard
A1: GIT AUDIT REPORT — SOFTWARE CI STATUS DASHBOARD
A2: Generated: February 2026 | All KPIs are formula-driven from Raw Data sheet
A4: Total CIs Tracked | C4: Git Available | E4: Git Not Available | G4: Overall Adoption % | I4: Total Push Count | K4: Teams Tracked
A5: ='Team Summary'!B8 | C5: ='Team Summary'!C8 | E5: ='Team Summary'!D8 | G5: ='Team Summary'!E8 | I5: ='Team Summary'!F8 | K5: =5
A8: TEAM-WISE SUMMARY (click Team Summary tab for detail)
A9: Team | B9: Total CIs | C9: Git Avail. | D9: Git N/A | E9: Adoption % | F9: Total Pushes | G9: Avg Pushes/CI
A10: ='Team Summary'!A3 | B10: ='Team Summary'!B3 | C10: ='Team Summary'!C3 | D10: ='Team Summary'!D3 | E10: ='Team Summary'!E3 | F10: ='Team Summary'!F3 | G10: ='Team Summary'!G3
A11: ='Team Summary'!A4 | B11: ='Team Summary'!B4 | C11: ='Team Summary'!C4 | D11: ='Team Summary'!D4 | E11: ='Team Summary'!E4 | F11: ='Team Summary'!F4 | G11: ='Team Summary'!G4
A12: ='Team Summary'!A5 | B12: ='Team Summary'!B5 | C12: ='Team Summary'!C5 | D12: ='Team Summary'!D5 | E12: ='Team Summary'!E5 | F12: ='Team Summary'!F5 | G12: ='Team Summary'!G5
A13: ='Team Summary'!A6 | B13: ='Team Summary'!B6 | C13: ='Team Summary'!C6 | D13: ='Team Summary'!D6 | E13: ='Team Summary'!E6 | F13: ='Team Summary'!F6 | G13: ='Team Summary'!G6
A14: ='Team Summary'!A7 | B14: ='Team Summary'!B7 | C14: ='Team Summary'!C7 | D14: ='Team Summary'!D7 | E14: ='Team Summary'!E7 | F14: ='Team Summary'!F7 | G14: ='Team Summary'!G7
A15: GRAND TOTAL | B15: ='Team Summary'!B8 | C15: ='Team Summary'!C8 | D15: ='Team Summary'!D8 | E15: ='Team Summary'!E8 | F15: ='Team Summary'!F8 | G15: ='Team Summary'!G8

Sheet Raw Data
A1: Sl.No | B1: Project ID | C1: Product ID | D1: Software Product (CI) | E1: In-Charge | F1: Product Status | G1: Status | H1: Total Push Count | I1: First Push Date | J1: Last Push Date | K1: Duration (days) | L1: Git Availability | M1: Observations | N1: Team
A2: 1 | B2: YIA2822_FCR_MIG29-K1 | C2: DP-VPX-0224 | D2: DP-VPX-0224-V1-01-BRAM-LIBS-ARM-LIN5V10 | E2: Vishnu | F2: Testing Stage | G2: SETUP UNAVAILABLE | H2: 2 | I2: 2025-11-07 | J2: 2025-11-07 | K2: 0 | L2: Available | N2: Computing
A3: 2 | D3: DP-VPX-0224-V1-01-PL-LIBS-ARM-LIN5V10 | H3: 2 | I3: 2025-11-07 | J3: 2025-11-07 | K3: 0 | L3: Available | N3: Computing
A4: 3 | D4: DP-VPX-0224-V1-01-PLL-LIBS-ARM-LIN5V10 | H4: 2 | I4: 2025-11-07 | J4: 2025-11-07 | K4: 0 | L4: Available | N4: Computing
A5: 4 | D5: DP-VPX-0224-V1-01-PS-LIBS-ARM-LIN5V10 | H5: 2 | I5: 2025-11-07 | J5: 2025-11-07 | K5: 0 | L5: Available | N5: Computing
A6: 5 | D6: DP-VPX-0224-V1-01-RF-LIBS-ARM-LIN5V10 | H6: 2 | I6: 2025-11-07 | J6: 2025-11-07 | K6: 0 | L6: Available | N6: Computing
A7: 6 | D7: DP-VPX-0224-V1-01-RFDC-LIBS-ARM-LIN5V10 | H7: 2 | I7: 2025-11-07 | J7: 2025-11-07 | K7: 0 | L7: Available | N7: Computing
A8: 7 | D8: DP-VPX-0224-V1-01-AS-ARM-LIN5V10 | H8: 7 | I8: 2025-07-25 | J8: 2025-11-07 | K8: 105 | L8: Available | N8: Computing
A9: 8 | D9: DP-VPX-0224-V1-01-AS-X86-W10 | H9: 4 | I9: 2025-07-25 | J9: 2025-11-07 | K9: 105 | L9: Available | N9: Computing
A10: 9 | D10: DP-VPX-0224-V1-01-DS-ARM-LIN5V10 | H10: 6 | I10: 2025-07-25 | J10: 2025-11-07 | K10: 105 | L10: Available | N10: Computing
A11: 10 | C11: DP-VPX-0227 | D11: DP-VPX-0227-V1-01-AS-ATP-ARM-LIN5V04 | F11: Testing Stage | G11: QAC | H11: 8 | I11: 2025-07-25 | J11: 2025-11-13 | K11: 111 | L11: Available | N11: Computing
A12: 11 | D12: DP-VPX-0227-V1-01-AS-AUTOMATION-ARM-LIN5V04 | H12: 2 | I12: 2025-07-25 | J12: 2025-09-01 | K12: 38 | L12: Available | N12: Computing
A13: 12 | D13: DP-VPX-0227-V1-01-AS-HSDC-AUTO-X86-W10-1V00 | H13: 2 | I13: 2025-07-25 | J13: 2025-09-01 | K13: 38 | L13: Available | N13: Computing
A14: 13 | D14: DP-VPX-0227-V1-01-DS-ARM-LIN5V04 | H14: 2 | I14: 2025-07-25 | J14: 2025-09-01 | K14: 38 | L14: Available | N14: Computing
A15: 14 | D15: DP-VPX-0227-V1-01-LIBS-ARM-LIN5V04 | H15: 7 | I15: 2025-07-25 | J15: 2025-11-13 | K15: 111 | L15: Available | N15: Computing
A16: 15 | C16: DP-VPX-2003 | D16: DP-VPX-2003-V1-01-AS-ARM-LIN5V10 | F16: Testing Stage | G16: ON HOLD | H16: 20 | I16: 2025-07-25 | J16: 2026-02-02 | K16: 192 | L16: Available | N16: Computing
A17: 16 | D17: DP-VPX-2003-V1-01-DS-ARM-LIN5V10 | H17: 9 | I17: 2025-07-25 | J17: 2026-02-02 | K17: 192 | L17: Available | N17: Computing
A18: 17 | D18: DP-VPX-2003-V1-01-LIBS-ARM-LIN5V10 | H18: 8 | I18: 2025-07-25 | J18: 2026-02-02 | K18: 192 | L18: Available | N18: Computing
A19: 18 | C19: DP-VPX-5792 | D19: DP-VPX-5792-V1-01-AS-PPC-LIN4V20 | F19: Testing Stage | G19: UNDER PROGRESS | H19: 6 | I19: 2025-07-25 | J19: 2025-11-14 | K19: 112 | L19: Available | N19: Computing
A20: 19 | D20: DP-VPX-5792-V1-01-DS-PPC-LIN4V20 | H20: 11 | I20: 2025-07-25 | J20: 2025-12-17 | K20: 145 | L20: Available | N20: Computing
A21: 20 | D21: DP-VPX-5792-V1-01-LIBS-PPC-LIN4V20 | H21: 11 | I21: 2025-07-25 | J21: 2025-11-27 | K21: 125 | L21: Available | N21: Computing
A22: 21 | C22: DP-VPX-7154 | D22: DP-VPX-7154-V1-01-AS-W10 | E22: Shiva Parvathi | F22: Requirement Stage | G22: UNDER PROGRESS | H22: 2 | I22: 2026-01-28 | J22: 2026-01-28 | K22: 0 | L22: Available | N22: Computing
A23: 22 | B23: YEA2876 | C23: DP-SPL-0244 | D23: DP-SPL-0244-600-V1-01-AS-ARM-LIN6V12 | E23: Narendra | F23: Testing Stage | G23: ON HOLD | H23: 3 | I23: 2025-11-13 | J23: 2025-11-13 | K23: 0 | L23: Available | N23: Computing
A24: 23 | D24: DP-SPL-0244-600-V1-01-AS-X86_64-W10 | H24: 1 | I24: 2025-11-13 | J24: 2025-11-13 | K24: 0 | L24: Available | N24: Computing
A25: 24 | D25: DP-SPL-0244-600-V1-01-LIBS-X86_64-W10 | H25: 1 | I25: 2025-11-13 | J25: 2025-11-13 | K25: 0 | L25: Available | N25: Computing
A26: 25 | D26: DP-SPL-0244-660-V1-01-LIBS-ARM-LIN6V12 | H26: 8 | I26: 2025-11-13 | J26: 2025-11-18 | K26: 5 | L26: Available | N26: Computing
A27: 26 | C27: DP-DSP-8208 | D27: DP-DSP-8208-660-V1-01-AS-ARM-LIN6V12 | F27: Testing Stage | G27: UNDER PROGRESS | H27: 9 | I27: 2025-11-13 | J27: 2026-02-05 | K27: 84 | L27: Available | N27: Computing
A28: 27 | D28: DP-DSP-8208-660-V1-01-AS-X86_64-W10 | H28: 8 | I28: 2025-11-13 | J28: 2026-02-05 | K28: 84 | L28: Available | N28: Computing
A29: 28 | D29: DP-DSP-8208-660-V1-01-LIBS-ARM-LIN6V12 | H29: 4 | I29: 2025-11-13 | J29: 2025-12-04 | K29: 21 | L29: Available | N29: Computing
A30: 29 | D30: DP-DSP-8208-660-V1-01-LIBS-X86_64-W10 | H30: 1 | I30: 2025-11-13 | J30: 2025-11-13 | K30: 0 | L30: Available | N30: Computing
A31: 30 | B31: YEB2935 | C31: DP-VPX-0233 | D31: DP-VPX-0233 | E31: Gowthami | F31: Testing Stage | G31: QAC | H31: 4 | I31: 2026-01-12 | J31: 2026-01-13 | K31: 1 | L31: Available | N31: Computing
A32: 31 | D32: DP-VPX-0233-V1-01-AS-ATP-ARM-LIN5V04 | H32: 8 | I32: 2025-07-25 | J32: 2025-11-18 | K32: 116 | L32: Available | N32: Computing
A33: 32 | D33: DP-VPX-0233-V1-01-AS-AUTOMATION-ARM-LIN5V04 | H33: 6 | I33: 2025-07-25 | J33: 2025-11-10 | K33: 108 | L33: Available | N33: Computing
A34: 33 | D34: DP-VPX-0233-V1-01-AS-HSDC-AUTO-X86-W10 | H34: 8 | I34: 2025-07-25 | J34: 2025-11-10 | K34: 108 | L34: Available | N34: Computing
A35: 34 | D35: DP-VPX-0233-V1-01-DS-ARM-LIN5V04 | H35: 6 | I35: 2025-07-25 | J35: 2025-11-10 | K35: 108 | L35: Available | N35: Computing
A36: 35 | D36: DP-VPX-0233-V1-01-LIBS-ARM-LIN5V04 | H36: 8 | I36: 2025-07-25 | J36: 2025-11-07 | K36: 105 | L36: Available | N36: Computing
A37: 36 | B37: YEA2918 | C37: DP-OBC-8178 | D37: DP-OBC-8178-663-V1-01-AS-ARINC615A-DL-X86_64-LIN5V14 | E37: Mohamed Ali | F37: Customer Test/Response | G37: COMPLETED | H37: 4 | I37: 2025-08-11 | J37: 2025-08-13 | K37: 2 | L37: Available | N37: Computing
A38: 37 | D38: DP-OBC-8178-663-V1-01-AS-ARINC615A-THW-X86_64-LIN5V14 | H38: 3 | I38: 2025-08-11 | J38: 2025-08-13 | K38: 2 | L38: Available | N38: Computing
A39: 38 | D39: DP-OBC-8178-663-V1-01-AS-SIM-SU-X86-W10 | H39: 3 | I39: 2025-11-20 | J39: 2025-11-20 | K39: 0 | L39: Available | N39: Computing
A40: 39 | D40: DP-OBC-8178-663-V1-01-AS-SIM-PU-X86-W10 | H40: 5 | I40: 2025-08-11 | J40: 2026-01-07 | K40: 149 | L40: Available | N40: Computing
...

Sheet Team Summary
A1: GIT AUDIT — TEAM-WISE SUMMARY (Formula-Driven)
A2: Team | B2: Total CIs | C2: Git Available | D2: Git Not Available | E2: Adoption % | F2: Total Pushes | G2: Avg Pushes/CI
A3: AGM | B3: =COUNTIF('Raw Data'!N$2:N$546,A3) | C3: =COUNTIFS('Raw Data'!N$2:N$546,A3,'Raw Data'!L$2:L$546,"Available")+COUNTIFS('Raw Data'!N$2:N$546,A3,'Raw Data'!L$2:L$546,"Yes") | D3: =B3-C3 | E3: =IF(B3>0,C3/B3,0) | F3: =SUMIF('Raw Data'!N$2:N$546,A3,'Raw Data'!H$2:H$546) | G3: =IF(B3>0,F3/B3,0)
A4: Application | B4: =COUNTIF('Raw Data'!N$2:N$546,A4) | C4: =COUNTIFS('Raw Data'!N$2:N$546,A4,'Raw Data'!L$2:L$546,"Available")+COUNTIFS('Raw Data'!N$2:N$546,A4,'Raw Data'!L$2:L$546,"Yes") | D4: =B4-C4 | E4: =IF(B4>0,C4/B4,0) | F4: =SUMIF('Raw Data'!N$2:N$546,A4,'Raw Data'!H$2:H$546) | G4: =IF(B4>0,F4/B4,0)
A5: BSP | B5: =COUNTIF('Raw Data'!N$2:N$546,A5) | C5: =COUNTIFS('Raw Data'!N$2:N$546,A5,'Raw Data'!L$2:L$546,"Available")+COUNTIFS('Raw Data'!N$2:N$546,A5,'Raw Data'!L$2:L$546,"Yes") | D5: =B5-C5 | E5: =IF(B5>0,C5/B5,0) | F5: =SUMIF('Raw Data'!N$2:N$546,A5,'Raw Data'!H$2:H$546) | G5: =IF(B5>0,F5/B5,0)
A6: Computing | B6: =COUNTIF('Raw Data'!N$2:N$546,A6) | C6: =COUNTIFS('Raw Data'!N$2:N$546,A6,'Raw Data'!L$2:L$546,"Available")+COUNTIFS('Raw Data'!N$2:N$546,A6,'Raw Data'!L$2:L$546,"Yes") | D6: =B6-C6 | E6: =IF(B6>0,C6/B6,0) | F6: =SUMIF('Raw Data'!N$2:N$546,A6,'Raw Data'!H$2:H$546) | G6: =IF(B6>0,F6/B6,0)
A7: RAD | B7: =COUNTIF('Raw Data'!N$2:N$546,A7) | C7: =COUNTIFS('Raw Data'!N$2:N$546,A7,'Raw Data'!L$2:L$546,"Available")+COUNTIFS('Raw Data'!N$2:N$546,A7,'Raw Data'!L$2:L$546,"Yes") | D7: =B7-C7 | E7: =IF(B7>0,C7/B7,0) | F7: =SUMIF('Raw Data'!N$2:N$546,A7,'Raw Data'!H$2:H$546) | G7: =IF(B7>0,F7/B7,0)
A8: GRAND TOTAL | B8: =SUM(B3:B7) | C8: =SUM(C3:C7) | D8: =SUM(D3:D7) | E8: =IF(B8>0,C8/B8,0) | F8: =SUM(F3:F7) | G8: =IF(B8>0,F8/B8,0)

Sheet Charts
A1: GIT AUDIT — VISUAL ANALYSIS
A3: Team | B3: Git Available | C3: Git Not Available
A4: ='Team Summary'!A3 | B4: ='Team Summary'!C3 | C4: ='Team Summary'!D3
A5: ='Team Summary'!A4 | B5: ='Team Summary'!C4 | C5: ='Team Summary'!D4
A6: ='Team Summary'!A5 | B6: ='Team Summary'!C5 | C6: ='Team Summary'!D5
A7: ='Team Summary'!A6 | B7: ='Team Summary'!C6 | C7: ='Team Summary'!D6
A8: ='Team Summary'!A7 | B8: ='Team Summary'!C7 | C8: ='Team Summary'!D7
A11: Team | B11: Adoption %
A12: ='Team Summary'!A3 | B12: ='Team Summary'!E3
A13: ='Team Summary'!A4 | B13: ='Team Summary'!E4
A14: ='Team Summary'!A5 | B14: ='Team Summary'!E5
A15: ='Team Summary'!A6 | B15: ='Team Summary'!E6
A16: ='Team Summary'!A7 | B16: ='Team Summary'!E7
A19: Status | B19: Count
A20: Git Available | B20: ='Team Summary'!C8
A21: Git Not Available | B21: ='Team Summary'!D8

Sheet Product Status
A1: PRODUCT-WISE GIT AVAILABILITY (Formula-Driven)
A2: Team | B2: Product ID | C2: Total CIs | D2: Git Available | E2: Git Not Available | F2: Adoption %
A3: AGM | B3: DP-COM-8031-630 | C3: =COUNTIF('Raw Data'!C$2:C$546,B3) | D3: =COUNTIFS('Raw Data'!C$2:C$546,B3,'Raw Data'!L$2:L$546,"Available")+COUNTIFS('Raw Data'!C$2:C$546,B3,'Raw Data'!L$2:L$546,"Yes") | E3: =C3-D3 | F3: =IF(C3>0,D3/C3,0)
A4: AGM | B4: DP-COM-8031-633 | C4: =COUNTIF('Raw Data'!C$2:C$546,B4) | D4: =COUNTIFS('Raw Data'!C$2:C$546,B4,'Raw Data'!L$2:L$546,"Available")+COUNTIFS('Raw Data'!C$2:C$546,B4,'Raw Data'!L$2:L$546,"Yes") | E4: =C4-D4 | F4: =IF(C4>0,D4/C4,0)
A5: AGM | B5: DP-CRF-2213 | C5: =COUNTIF('Raw Data'!C$2:C$546,B5) | D5: =COUNTIFS('Raw Data'!C$2:C$546,B5,'Raw Data'!L$2:L$546,"Available")+COUNTIFS('Raw Data'!C$2:C$546,B5,'Raw Data'!L$2:L$546,"Yes") | E5: =C5-D5 | F5: =IF(C5>0,D5/C5,0)
A6: AGM | B6: DP-CRF-2519 | C6: =COUNTIF('Raw Data'!C$2:C$546,B6) | D6: =COUNTIFS('Raw Data'!C$2:C$546,B6,'Raw Data'!L$2:L$546,"Available")+COUNTIFS('Raw Data'!C$2:C$546,B6,'Raw Data'!L$2:L$546,"Yes") | E6: =C6-D6 | F6: =IF(C6>0,D6/C6,0)
A7: AGM | B7: DP-CRF-5366 | C7: =COUNTIF('Raw Data'!C$2:C$546,B7) | D7: =COUNTIFS('Raw Data'!C$2:C$546,B7,'Raw Data'!L$2:L$546,"Available")+COUNTIFS('Raw Data'!C$2:C$546,B7,'Raw Data'!L$2:L$546,"Yes") | E7: =C7-D7 | F7: =IF(C7>0,D7/C7,0)
A8: AGM | B8: DP-CRF-5369 | C8: =COUNTIF('Raw Data'!C$2:C$546,B8) | D8: =COUNTIFS('Raw Data'!C$2:C$546,B8,'Raw Data'!L$2:L$546,"Available")+COUNTIFS('Raw Data'!C$2:C$546,B8,'Raw Data'!L$2:L$546,"Yes") | E8: =C8-D8 | F8: =IF(C8>0,D8/C8,0)
A9: AGM | B9: DP-CRF-7556 PLL | C9: =COUNTIF('Raw Data'!C$2:C$546,B9) | D9: =COUNTIFS('Raw Data'!C$2:C$546,B9,'Raw Data'!L$2:L$546,"Available")+COUNTIFS('Raw Data'!C$2:C$546,B9,'Raw Data'!L$2:L$546,"Yes") | E9: =C9-D9 | F9: =IF(C9>0,D9/C9,0)
A10: AGM | B10: DP-ESM-1073-6333-HF-RPE | C10: =COUNTIF('Raw Data'!C$2:C$546,B10) | D10: =COUNTIFS('Raw Data'!C$2:C$546,B10,'Raw Data'!L$2:L$546,"Available")+COUNTIFS('Raw Data'!C$2:C$546,B10,'Raw Data'!L$2:L$546,"Yes") | E10: =C10-D10 | F10: =IF(C10>0,D10/C10,0)
A11: AGM | B11: DP-ESM-1074-6000-VUSHF-RPE | C11: =COUNTIF('Raw Data'!C$2:C$546,B11) | D11: =COUNTIFS('Raw Data'!C$2:C$546,B11,'Raw Data'!L$2:L$546,"Available")+COUNTIFS('Raw Data'!C$2:C$546,B11,'Raw Data'!L$2:L$546,"Yes") | E11: =C11-D11 | F11: =IF(C11>0,D11/C11,0)
A12: AGM | B12: DP-ESM-1095-600-AIDF | C12: =COUNTIF('Raw Data'!C$2:C$546,B12) | D12: =COUNTIFS('Raw Data'!C$2:C$546,B12,'Raw Data'!L$2:L$546,"Available")+COUNTIFS('Raw Data'!C$2:C$546,B12,'Raw Data'!L$2:L$546,"Yes") | E12: =C12-D12 | F12: =IF(C12>0,D12/C12,0)
A13: AGM | B13: DP-ESM-1095-603-MIDF | C13: =COUNTIF('Raw Data'!C$2:C$546,B13) | D13: =COUNTIFS('Raw Data'!C$2:C$546,B13,'Raw Data'!L$2:L$546,"Available")+COUNTIFS('Raw Data'!C$2:C$546,B13,'Raw Data'!L$2:L$546,"Yes") | E13: =C13-D13 | F13: =IF(C13>0,D13/C13,0)
A14: AGM | B14: DP-ESM-1098-600-CFDF | C14: =COUNTIF('Raw Data'!C$2:C$546,B14) | D14: =COUNTIFS('Raw Data'!C$2:C$546,B14,'Raw Data'!L$2:L$546,"Available")+COUNTIFS('Raw Data'!C$2:C$546,B14,'Raw Data'!L$2:L$546,"Yes") | E14: =C14-D14 | F14: =IF(C14>0,D14/C14,0)
... A203: RAD | B203: DP-SWR-8005 | C203: =COUNTIF('Raw Data'!C$2:C$546,B203) | D203: =COUNTIFS('Raw Data'!C$2:C$546,B203,'Raw Data'!L$2:L$546,"Available")+COUNTIFS('Raw Data'!C$2:C$546,B203,'Raw Data'!L$2:L$546,"Yes") | E203: =C203-D203 | F203: =IF(C203>0,D203/C203,0)
